Internal Server Error: /filter/
Traceback (most recent call last):
  File "/home/mydjangoproject/myfiles/myvenv/lib/python3.10/site-packages/asgiref/sync.py", line 534, in thread_handler
    raise exc_info[1]
  File "/home/mydjangoproject/myfiles/myvenv/lib/python3.10/site-packages/django/core/handlers/exception.py", line 42, in inner
    response = await get_response(request)
  File "/home/mydjangoproject/myfiles/myvenv/lib/python3.10/site-packages/django/core/handlers/base.py", line 253, in _get_response_async
    response = await wrapped_callback(
  File "/home/mydjangoproject/myfiles/myvenv/lib/python3.10/site-packages/asgiref/sync.py", line 479, in __call__
    ret: _R = await loop.run_in_executor(
  File "/usr/lib/python3.10/concurrent/futures/thread.py", line 58, in run
    result = self.fn(*self.args, **self.kwargs)
  File "/home/mydjangoproject/myfiles/myvenv/lib/python3.10/site-packages/asgiref/sync.py", line 538, in thread_handler
    return func(*args, **kwargs)
  File "/home/mydjangoproject/myfiles/myvenv/lib/python3.10/site-packages/django/views/decorators/csrf.py", line 54, in wrapped_view
    return view_func(*args, **kwargs)
  File "/home/mydjangoproject/myfiles/myvenv/lib/python3.10/site-packages/django/views/generic/base.py", line 84, in view
    return self.dispatch(request, *args, **kwargs)
  File "/home/mydjangoproject/myfiles/myvenv/lib/python3.10/site-packages/rest_framework/views.py", line 509, in dispatch
    response = self.handle_exception(exc)
  File "/home/mydjangoproject/myfiles/myvenv/lib/python3.10/site-packages/rest_framework/views.py", line 469, in handle_exception
    self.raise_uncaught_exception(exc)
  File "/home/mydjangoproject/myfiles/myvenv/lib/python3.10/site-packages/rest_framework/views.py", line 480, in raise_uncaught_exception
    raise exc
  File "/home/mydjangoproject/myfiles/myvenv/lib/python3.10/site-packages/rest_framework/views.py", line 506, in dispatch
    response = handler(request, *args, **kwargs)
  File "/home/mydjangoproject/myfiles/alertlog/views.py", line 146, in get
    if  time1 & time2 :
TypeError: unsupported operand type(s) for &: 'NoneType' and 'NoneType'
Internal Server Error: /filter/
Traceback (most recent call last):
  File "/home/mydjangoproject/myfiles/myvenv/lib/python3.10/site-packages/asgiref/sync.py", line 534, in thread_handler
    raise exc_info[1]
  File "/home/mydjangoproject/myfiles/myvenv/lib/python3.10/site-packages/django/core/handlers/exception.py", line 42, in inner
    response = await get_response(request)
  File "/home/mydjangoproject/myfiles/myvenv/lib/python3.10/site-packages/django/core/handlers/base.py", line 253, in _get_response_async
    response = await wrapped_callback(
  File "/home/mydjangoproject/myfiles/myvenv/lib/python3.10/site-packages/asgiref/sync.py", line 479, in __call__
    ret: _R = await loop.run_in_executor(
  File "/usr/lib/python3.10/concurrent/futures/thread.py", line 58, in run
    result = self.fn(*self.args, **self.kwargs)
  File "/home/mydjangoproject/myfiles/myvenv/lib/python3.10/site-packages/asgiref/sync.py", line 538, in thread_handler
    return func(*args, **kwargs)
  File "/home/mydjangoproject/myfiles/myvenv/lib/python3.10/site-packages/django/views/decorators/csrf.py", line 54, in wrapped_view
    return view_func(*args, **kwargs)
  File "/home/mydjangoproject/myfiles/myvenv/lib/python3.10/site-packages/django/views/generic/base.py", line 84, in view
    return self.dispatch(request, *args, **kwargs)
  File "/home/mydjangoproject/myfiles/myvenv/lib/python3.10/site-packages/rest_framework/views.py", line 509, in dispatch
    response = self.handle_exception(exc)
  File "/home/mydjangoproject/myfiles/myvenv/lib/python3.10/site-packages/rest_framework/views.py", line 469, in handle_exception
    self.raise_uncaught_exception(exc)
  File "/home/mydjangoproject/myfiles/myvenv/lib/python3.10/site-packages/rest_framework/views.py", line 480, in raise_uncaught_exception
    raise exc
  File "/home/mydjangoproject/myfiles/myvenv/lib/python3.10/site-packages/rest_framework/views.py", line 506, in dispatch
    response = handler(request, *args, **kwargs)
  File "/home/mydjangoproject/myfiles/alertlog/views.py", line 146, in get
    if  time1 & time2 :
TypeError: unsupported operand type(s) for &: 'NoneType' and 'NoneType'
Internal Server Error: /filter/
Traceback (most recent call last):
  File "/home/mydjangoproject/myfiles/myvenv/lib/python3.10/site-packages/asgiref/sync.py", line 534, in thread_handler
    raise exc_info[1]
  File "/home/mydjangoproject/myfiles/myvenv/lib/python3.10/site-packages/django/core/handlers/exception.py", line 42, in inner
    response = await get_response(request)
  File "/home/mydjangoproject/myfiles/myvenv/lib/python3.10/site-packages/django/core/handlers/base.py", line 253, in _get_response_async
    response = await wrapped_callback(
  File "/home/mydjangoproject/myfiles/myvenv/lib/python3.10/site-packages/asgiref/sync.py", line 479, in __call__
    ret: _R = await loop.run_in_executor(
  File "/usr/lib/python3.10/concurrent/futures/thread.py", line 58, in run
    result = self.fn(*self.args, **self.kwargs)
  File "/home/mydjangoproject/myfiles/myvenv/lib/python3.10/site-packages/asgiref/sync.py", line 538, in thread_handler
    return func(*args, **kwargs)
  File "/home/mydjangoproject/myfiles/myvenv/lib/python3.10/site-packages/django/views/decorators/csrf.py", line 54, in wrapped_view
    return view_func(*args, **kwargs)
  File "/home/mydjangoproject/myfiles/myvenv/lib/python3.10/site-packages/django/views/generic/base.py", line 84, in view
    return self.dispatch(request, *args, **kwargs)
  File "/home/mydjangoproject/myfiles/myvenv/lib/python3.10/site-packages/rest_framework/views.py", line 509, in dispatch
    response = self.handle_exception(exc)
  File "/home/mydjangoproject/myfiles/myvenv/lib/python3.10/site-packages/rest_framework/views.py", line 469, in handle_exception
    self.raise_uncaught_exception(exc)
  File "/home/mydjangoproject/myfiles/myvenv/lib/python3.10/site-packages/rest_framework/views.py", line 480, in raise_uncaught_exception
    raise exc
  File "/home/mydjangoproject/myfiles/myvenv/lib/python3.10/site-packages/rest_framework/views.py", line 506, in dispatch
    response = handler(request, *args, **kwargs)
  File "/home/mydjangoproject/myfiles/alertlog/views.py", line 146, in get
    if  time1 & time2 :
TypeError: unsupported operand type(s) for &: 'NoneType' and 'NoneType'
Internal Server Error: /filter/
Traceback (most recent call last):
  File "/home/mydjangoproject/myfiles/myvenv/lib/python3.10/site-packages/asgiref/sync.py", line 534, in thread_handler
    raise exc_info[1]
  File "/home/mydjangoproject/myfiles/myvenv/lib/python3.10/site-packages/django/core/handlers/exception.py", line 42, in inner
    response = await get_response(request)
  File "/home/mydjangoproject/myfiles/myvenv/lib/python3.10/site-packages/django/core/handlers/base.py", line 253, in _get_response_async
    response = await wrapped_callback(
  File "/home/mydjangoproject/myfiles/myvenv/lib/python3.10/site-packages/asgiref/sync.py", line 479, in __call__
    ret: _R = await loop.run_in_executor(
  File "/usr/lib/python3.10/concurrent/futures/thread.py", line 58, in run
    result = self.fn(*self.args, **self.kwargs)
  File "/home/mydjangoproject/myfiles/myvenv/lib/python3.10/site-packages/asgiref/sync.py", line 538, in thread_handler
    return func(*args, **kwargs)
  File "/home/mydjangoproject/myfiles/myvenv/lib/python3.10/site-packages/django/views/decorators/csrf.py", line 54, in wrapped_view
    return view_func(*args, **kwargs)
  File "/home/mydjangoproject/myfiles/myvenv/lib/python3.10/site-packages/django/views/generic/base.py", line 84, in view
    return self.dispatch(request, *args, **kwargs)
  File "/home/mydjangoproject/myfiles/myvenv/lib/python3.10/site-packages/rest_framework/views.py", line 509, in dispatch
    response = self.handle_exception(exc)
  File "/home/mydjangoproject/myfiles/myvenv/lib/python3.10/site-packages/rest_framework/views.py", line 469, in handle_exception
    self.raise_uncaught_exception(exc)
  File "/home/mydjangoproject/myfiles/myvenv/lib/python3.10/site-packages/rest_framework/views.py", line 480, in raise_uncaught_exception
    raise exc
  File "/home/mydjangoproject/myfiles/myvenv/lib/python3.10/site-packages/rest_framework/views.py", line 506, in dispatch
    response = handler(request, *args, **kwargs)
  File "/home/mydjangoproject/myfiles/alertlog/views.py", line 146, in get
    if  time1 & time2 :
TypeError: unsupported operand type(s) for &: 'NoneType' and 'NoneType'
Internal Server Error: /filter/
Traceback (most recent call last):
  File "/home/mydjangoproject/myfiles/myvenv/lib/python3.10/site-packages/asgiref/sync.py", line 534, in thread_handler
    raise exc_info[1]
  File "/home/mydjangoproject/myfiles/myvenv/lib/python3.10/site-packages/django/core/handlers/exception.py", line 42, in inner
    response = await get_response(request)
  File "/home/mydjangoproject/myfiles/myvenv/lib/python3.10/site-packages/django/core/handlers/base.py", line 253, in _get_response_async
    response = await wrapped_callback(
  File "/home/mydjangoproject/myfiles/myvenv/lib/python3.10/site-packages/asgiref/sync.py", line 479, in __call__
    ret: _R = await loop.run_in_executor(
  File "/usr/lib/python3.10/concurrent/futures/thread.py", line 58, in run
    result = self.fn(*self.args, **self.kwargs)
  File "/home/mydjangoproject/myfiles/myvenv/lib/python3.10/site-packages/asgiref/sync.py", line 538, in thread_handler
    return func(*args, **kwargs)
  File "/home/mydjangoproject/myfiles/myvenv/lib/python3.10/site-packages/django/views/decorators/csrf.py", line 54, in wrapped_view
    return view_func(*args, **kwargs)
  File "/home/mydjangoproject/myfiles/myvenv/lib/python3.10/site-packages/django/views/generic/base.py", line 84, in view
    return self.dispatch(request, *args, **kwargs)
  File "/home/mydjangoproject/myfiles/myvenv/lib/python3.10/site-packages/rest_framework/views.py", line 509, in dispatch
    response = self.handle_exception(exc)
  File "/home/mydjangoproject/myfiles/myvenv/lib/python3.10/site-packages/rest_framework/views.py", line 469, in handle_exception
    self.raise_uncaught_exception(exc)
  File "/home/mydjangoproject/myfiles/myvenv/lib/python3.10/site-packages/rest_framework/views.py", line 480, in raise_uncaught_exception
    raise exc
  File "/home/mydjangoproject/myfiles/myvenv/lib/python3.10/site-packages/rest_framework/views.py", line 506, in dispatch
    response = handler(request, *args, **kwargs)
  File "/home/mydjangoproject/myfiles/alertlog/views.py", line 146, in get
    if  time1 & time2 :
TypeError: unsupported operand type(s) for &: 'NoneType' and 'NoneType'
Internal Server Error: /filter/
Traceback (most recent call last):
  File "/home/mydjangoproject/myfiles/myvenv/lib/python3.10/site-packages/asgiref/sync.py", line 534, in thread_handler
    raise exc_info[1]
  File "/home/mydjangoproject/myfiles/myvenv/lib/python3.10/site-packages/django/core/handlers/exception.py", line 42, in inner
    response = await get_response(request)
  File "/home/mydjangoproject/myfiles/myvenv/lib/python3.10/site-packages/django/core/handlers/base.py", line 253, in _get_response_async
    response = await wrapped_callback(
  File "/home/mydjangoproject/myfiles/myvenv/lib/python3.10/site-packages/asgiref/sync.py", line 479, in __call__
    ret: _R = await loop.run_in_executor(
  File "/usr/lib/python3.10/concurrent/futures/thread.py", line 58, in run
    result = self.fn(*self.args, **self.kwargs)
  File "/home/mydjangoproject/myfiles/myvenv/lib/python3.10/site-packages/asgiref/sync.py", line 538, in thread_handler
    return func(*args, **kwargs)
  File "/home/mydjangoproject/myfiles/myvenv/lib/python3.10/site-packages/django/views/decorators/csrf.py", line 54, in wrapped_view
    return view_func(*args, **kwargs)
  File "/home/mydjangoproject/myfiles/myvenv/lib/python3.10/site-packages/django/views/generic/base.py", line 84, in view
    return self.dispatch(request, *args, **kwargs)
  File "/home/mydjangoproject/myfiles/myvenv/lib/python3.10/site-packages/rest_framework/views.py", line 509, in dispatch
    response = self.handle_exception(exc)
  File "/home/mydjangoproject/myfiles/myvenv/lib/python3.10/site-packages/rest_framework/views.py", line 469, in handle_exception
    self.raise_uncaught_exception(exc)
  File "/home/mydjangoproject/myfiles/myvenv/lib/python3.10/site-packages/rest_framework/views.py", line 480, in raise_uncaught_exception
    raise exc
  File "/home/mydjangoproject/myfiles/myvenv/lib/python3.10/site-packages/rest_framework/views.py", line 506, in dispatch
    response = handler(request, *args, **kwargs)
  File "/home/mydjangoproject/myfiles/alertlog/views.py", line 143, in get
    filterlogs = filterlogs.filter(Q(hostname__icontains=hostname))
NameError: name 'Q' is not defined
Internal Server Error: /filter/
Traceback (most recent call last):
  File "/home/mydjangoproject/myfiles/myvenv/lib/python3.10/site-packages/asgiref/sync.py", line 534, in thread_handler
    raise exc_info[1]
  File "/home/mydjangoproject/myfiles/myvenv/lib/python3.10/site-packages/django/core/handlers/exception.py", line 42, in inner
    response = await get_response(request)
  File "/home/mydjangoproject/myfiles/myvenv/lib/python3.10/site-packages/django/core/handlers/base.py", line 253, in _get_response_async
    response = await wrapped_callback(
  File "/home/mydjangoproject/myfiles/myvenv/lib/python3.10/site-packages/asgiref/sync.py", line 479, in __call__
    ret: _R = await loop.run_in_executor(
  File "/usr/lib/python3.10/concurrent/futures/thread.py", line 58, in run
    result = self.fn(*self.args, **self.kwargs)
  File "/home/mydjangoproject/myfiles/myvenv/lib/python3.10/site-packages/asgiref/sync.py", line 538, in thread_handler
    return func(*args, **kwargs)
  File "/home/mydjangoproject/myfiles/myvenv/lib/python3.10/site-packages/django/views/decorators/csrf.py", line 54, in wrapped_view
    return view_func(*args, **kwargs)
  File "/home/mydjangoproject/myfiles/myvenv/lib/python3.10/site-packages/django/views/generic/base.py", line 84, in view
    return self.dispatch(request, *args, **kwargs)
  File "/home/mydjangoproject/myfiles/myvenv/lib/python3.10/site-packages/rest_framework/views.py", line 509, in dispatch
    response = self.handle_exception(exc)
  File "/home/mydjangoproject/myfiles/myvenv/lib/python3.10/site-packages/rest_framework/views.py", line 469, in handle_exception
    self.raise_uncaught_exception(exc)
  File "/home/mydjangoproject/myfiles/myvenv/lib/python3.10/site-packages/rest_framework/views.py", line 480, in raise_uncaught_exception
    raise exc
  File "/home/mydjangoproject/myfiles/myvenv/lib/python3.10/site-packages/rest_framework/views.py", line 506, in dispatch
    response = handler(request, *args, **kwargs)
  File "/home/mydjangoproject/myfiles/alertlog/views.py", line 143, in get
    filterlogs = filterlogs.filter(Q(hostname__icontains=hostname))
NameError: name 'Q' is not defined
Internal Server Error: /filter/
Traceback (most recent call last):
  File "/home/mydjangoproject/myfiles/myvenv/lib/python3.10/site-packages/asgiref/sync.py", line 534, in thread_handler
    raise exc_info[1]
  File "/home/mydjangoproject/myfiles/myvenv/lib/python3.10/site-packages/django/core/handlers/exception.py", line 42, in inner
    response = await get_response(request)
  File "/home/mydjangoproject/myfiles/myvenv/lib/python3.10/site-packages/django/core/handlers/base.py", line 253, in _get_response_async
    response = await wrapped_callback(
  File "/home/mydjangoproject/myfiles/myvenv/lib/python3.10/site-packages/asgiref/sync.py", line 479, in __call__
    ret: _R = await loop.run_in_executor(
  File "/usr/lib/python3.10/concurrent/futures/thread.py", line 58, in run
    result = self.fn(*self.args, **self.kwargs)
  File "/home/mydjangoproject/myfiles/myvenv/lib/python3.10/site-packages/asgiref/sync.py", line 538, in thread_handler
    return func(*args, **kwargs)
  File "/home/mydjangoproject/myfiles/myvenv/lib/python3.10/site-packages/django/views/decorators/csrf.py", line 54, in wrapped_view
    return view_func(*args, **kwargs)
  File "/home/mydjangoproject/myfiles/myvenv/lib/python3.10/site-packages/django/views/generic/base.py", line 84, in view
    return self.dispatch(request, *args, **kwargs)
  File "/home/mydjangoproject/myfiles/myvenv/lib/python3.10/site-packages/rest_framework/views.py", line 509, in dispatch
    response = self.handle_exception(exc)
  File "/home/mydjangoproject/myfiles/myvenv/lib/python3.10/site-packages/rest_framework/views.py", line 469, in handle_exception
    self.raise_uncaught_exception(exc)
  File "/home/mydjangoproject/myfiles/myvenv/lib/python3.10/site-packages/rest_framework/views.py", line 480, in raise_uncaught_exception
    raise exc
  File "/home/mydjangoproject/myfiles/myvenv/lib/python3.10/site-packages/rest_framework/views.py", line 506, in dispatch
    response = handler(request, *args, **kwargs)
  File "/home/mydjangoproject/myfiles/alertlog/views.py", line 143, in get
    filterlogs = filterlogs.filter(Q(hostname__icontains=hostname))
NameError: name 'Q' is not defined
Internal Server Error: /filter/
Traceback (most recent call last):
  File "/home/mydjangoproject/myfiles/myvenv/lib/python3.10/site-packages/asgiref/sync.py", line 534, in thread_handler
    raise exc_info[1]
  File "/home/mydjangoproject/myfiles/myvenv/lib/python3.10/site-packages/django/core/handlers/exception.py", line 42, in inner
    response = await get_response(request)
  File "/home/mydjangoproject/myfiles/myvenv/lib/python3.10/site-packages/django/core/handlers/base.py", line 253, in _get_response_async
    response = await wrapped_callback(
  File "/home/mydjangoproject/myfiles/myvenv/lib/python3.10/site-packages/asgiref/sync.py", line 479, in __call__
    ret: _R = await loop.run_in_executor(
  File "/usr/lib/python3.10/concurrent/futures/thread.py", line 58, in run
    result = self.fn(*self.args, **self.kwargs)
  File "/home/mydjangoproject/myfiles/myvenv/lib/python3.10/site-packages/asgiref/sync.py", line 538, in thread_handler
    return func(*args, **kwargs)
  File "/home/mydjangoproject/myfiles/myvenv/lib/python3.10/site-packages/django/views/decorators/csrf.py", line 54, in wrapped_view
    return view_func(*args, **kwargs)
  File "/home/mydjangoproject/myfiles/myvenv/lib/python3.10/site-packages/django/views/generic/base.py", line 84, in view
    return self.dispatch(request, *args, **kwargs)
  File "/home/mydjangoproject/myfiles/myvenv/lib/python3.10/site-packages/rest_framework/views.py", line 509, in dispatch
    response = self.handle_exception(exc)
  File "/home/mydjangoproject/myfiles/myvenv/lib/python3.10/site-packages/rest_framework/views.py", line 469, in handle_exception
    self.raise_uncaught_exception(exc)
  File "/home/mydjangoproject/myfiles/myvenv/lib/python3.10/site-packages/rest_framework/views.py", line 480, in raise_uncaught_exception
    raise exc
  File "/home/mydjangoproject/myfiles/myvenv/lib/python3.10/site-packages/rest_framework/views.py", line 506, in dispatch
    response = handler(request, *args, **kwargs)
  File "/home/mydjangoproject/myfiles/alertlog/views.py", line 143, in get
    filterlogs = filterlogs.filter(Q(hostname__icontains=hostname))
NameError: name 'Q' is not defined
Internal Server Error: /filter/
Traceback (most recent call last):
  File "/home/mydjangoproject/myfiles/myvenv/lib/python3.10/site-packages/asgiref/sync.py", line 534, in thread_handler
    raise exc_info[1]
  File "/home/mydjangoproject/myfiles/myvenv/lib/python3.10/site-packages/django/core/handlers/exception.py", line 42, in inner
    response = await get_response(request)
  File "/home/mydjangoproject/myfiles/myvenv/lib/python3.10/site-packages/django/core/handlers/base.py", line 253, in _get_response_async
    response = await wrapped_callback(
  File "/home/mydjangoproject/myfiles/myvenv/lib/python3.10/site-packages/asgiref/sync.py", line 479, in __call__
    ret: _R = await loop.run_in_executor(
  File "/usr/lib/python3.10/concurrent/futures/thread.py", line 58, in run
    result = self.fn(*self.args, **self.kwargs)
  File "/home/mydjangoproject/myfiles/myvenv/lib/python3.10/site-packages/asgiref/sync.py", line 538, in thread_handler
    return func(*args, **kwargs)
  File "/home/mydjangoproject/myfiles/myvenv/lib/python3.10/site-packages/django/views/decorators/csrf.py", line 54, in wrapped_view
    return view_func(*args, **kwargs)
  File "/home/mydjangoproject/myfiles/myvenv/lib/python3.10/site-packages/django/views/generic/base.py", line 84, in view
    return self.dispatch(request, *args, **kwargs)
  File "/home/mydjangoproject/myfiles/myvenv/lib/python3.10/site-packages/rest_framework/views.py", line 509, in dispatch
    response = self.handle_exception(exc)
  File "/home/mydjangoproject/myfiles/myvenv/lib/python3.10/site-packages/rest_framework/views.py", line 469, in handle_exception
    self.raise_uncaught_exception(exc)
  File "/home/mydjangoproject/myfiles/myvenv/lib/python3.10/site-packages/rest_framework/views.py", line 480, in raise_uncaught_exception
    raise exc
  File "/home/mydjangoproject/myfiles/myvenv/lib/python3.10/site-packages/rest_framework/views.py", line 506, in dispatch
    response = handler(request, *args, **kwargs)
  File "/home/mydjangoproject/myfiles/alertlog/views.py", line 143, in get
    filterlogs = filterlogs.filter(Q(hostname__icontains=hostname))
NameError: name 'Q' is not defined
Internal Server Error: /filter/
Traceback (most recent call last):
  File "/home/mydjangoproject/myfiles/myvenv/lib/python3.10/site-packages/asgiref/sync.py", line 534, in thread_handler
    raise exc_info[1]
  File "/home/mydjangoproject/myfiles/myvenv/lib/python3.10/site-packages/django/core/handlers/exception.py", line 42, in inner
    response = await get_response(request)
  File "/home/mydjangoproject/myfiles/myvenv/lib/python3.10/site-packages/django/core/handlers/base.py", line 253, in _get_response_async
    response = await wrapped_callback(
  File "/home/mydjangoproject/myfiles/myvenv/lib/python3.10/site-packages/asgiref/sync.py", line 479, in __call__
    ret: _R = await loop.run_in_executor(
  File "/usr/lib/python3.10/concurrent/futures/thread.py", line 58, in run
    result = self.fn(*self.args, **self.kwargs)
  File "/home/mydjangoproject/myfiles/myvenv/lib/python3.10/site-packages/asgiref/sync.py", line 538, in thread_handler
    return func(*args, **kwargs)
  File "/home/mydjangoproject/myfiles/myvenv/lib/python3.10/site-packages/django/views/decorators/csrf.py", line 54, in wrapped_view
    return view_func(*args, **kwargs)
  File "/home/mydjangoproject/myfiles/myvenv/lib/python3.10/site-packages/django/views/generic/base.py", line 84, in view
    return self.dispatch(request, *args, **kwargs)
  File "/home/mydjangoproject/myfiles/myvenv/lib/python3.10/site-packages/rest_framework/views.py", line 509, in dispatch
    response = self.handle_exception(exc)
  File "/home/mydjangoproject/myfiles/myvenv/lib/python3.10/site-packages/rest_framework/views.py", line 469, in handle_exception
    self.raise_uncaught_exception(exc)
  File "/home/mydjangoproject/myfiles/myvenv/lib/python3.10/site-packages/rest_framework/views.py", line 480, in raise_uncaught_exception
    raise exc
  File "/home/mydjangoproject/myfiles/myvenv/lib/python3.10/site-packages/rest_framework/views.py", line 506, in dispatch
    response = handler(request, *args, **kwargs)
  File "/home/mydjangoproject/myfiles/alertlog/views.py", line 147, in get
    filterlogs = filterlogs.filter(timestamp__range(time1,time2))
NameError: name 'timestamp__range' is not defined
Internal Server Error: /filter/
Traceback (most recent call last):
  File "/home/mydjangoproject/myfiles/myvenv/lib/python3.10/site-packages/asgiref/sync.py", line 534, in thread_handler
    raise exc_info[1]
  File "/home/mydjangoproject/myfiles/myvenv/lib/python3.10/site-packages/django/core/handlers/exception.py", line 42, in inner
    response = await get_response(request)
  File "/home/mydjangoproject/myfiles/myvenv/lib/python3.10/site-packages/django/core/handlers/base.py", line 253, in _get_response_async
    response = await wrapped_callback(
  File "/home/mydjangoproject/myfiles/myvenv/lib/python3.10/site-packages/asgiref/sync.py", line 479, in __call__
    ret: _R = await loop.run_in_executor(
  File "/usr/lib/python3.10/concurrent/futures/thread.py", line 58, in run
    result = self.fn(*self.args, **self.kwargs)
  File "/home/mydjangoproject/myfiles/myvenv/lib/python3.10/site-packages/asgiref/sync.py", line 538, in thread_handler
    return func(*args, **kwargs)
  File "/home/mydjangoproject/myfiles/myvenv/lib/python3.10/site-packages/django/views/decorators/csrf.py", line 54, in wrapped_view
    return view_func(*args, **kwargs)
  File "/home/mydjangoproject/myfiles/myvenv/lib/python3.10/site-packages/django/views/generic/base.py", line 84, in view
    return self.dispatch(request, *args, **kwargs)
  File "/home/mydjangoproject/myfiles/myvenv/lib/python3.10/site-packages/rest_framework/views.py", line 509, in dispatch
    response = self.handle_exception(exc)
  File "/home/mydjangoproject/myfiles/myvenv/lib/python3.10/site-packages/rest_framework/views.py", line 469, in handle_exception
    self.raise_uncaught_exception(exc)
  File "/home/mydjangoproject/myfiles/myvenv/lib/python3.10/site-packages/rest_framework/views.py", line 480, in raise_uncaught_exception
    raise exc
  File "/home/mydjangoproject/myfiles/myvenv/lib/python3.10/site-packages/rest_framework/views.py", line 506, in dispatch
    response = handler(request, *args, **kwargs)
  File "/home/mydjangoproject/myfiles/alertlog/views.py", line 147, in get
    filterlogs = filterlogs.filter(timestamp__range(time1,time2))
NameError: name 'timestamp__range' is not defined
Internal Server Error: /filter/
Traceback (most recent call last):
  File "/home/mydjangoproject/myfiles/myvenv/lib/python3.10/site-packages/asgiref/sync.py", line 534, in thread_handler
    raise exc_info[1]
  File "/home/mydjangoproject/myfiles/myvenv/lib/python3.10/site-packages/django/core/handlers/exception.py", line 42, in inner
    response = await get_response(request)
  File "/home/mydjangoproject/myfiles/myvenv/lib/python3.10/site-packages/django/core/handlers/base.py", line 253, in _get_response_async
    response = await wrapped_callback(
  File "/home/mydjangoproject/myfiles/myvenv/lib/python3.10/site-packages/asgiref/sync.py", line 479, in __call__
    ret: _R = await loop.run_in_executor(
  File "/usr/lib/python3.10/concurrent/futures/thread.py", line 58, in run
    result = self.fn(*self.args, **self.kwargs)
  File "/home/mydjangoproject/myfiles/myvenv/lib/python3.10/site-packages/asgiref/sync.py", line 538, in thread_handler
    return func(*args, **kwargs)
  File "/home/mydjangoproject/myfiles/myvenv/lib/python3.10/site-packages/django/views/decorators/csrf.py", line 54, in wrapped_view
    return view_func(*args, **kwargs)
  File "/home/mydjangoproject/myfiles/myvenv/lib/python3.10/site-packages/django/views/generic/base.py", line 84, in view
    return self.dispatch(request, *args, **kwargs)
  File "/home/mydjangoproject/myfiles/myvenv/lib/python3.10/site-packages/rest_framework/views.py", line 509, in dispatch
    response = self.handle_exception(exc)
  File "/home/mydjangoproject/myfiles/myvenv/lib/python3.10/site-packages/rest_framework/views.py", line 469, in handle_exception
    self.raise_uncaught_exception(exc)
  File "/home/mydjangoproject/myfiles/myvenv/lib/python3.10/site-packages/rest_framework/views.py", line 480, in raise_uncaught_exception
    raise exc
  File "/home/mydjangoproject/myfiles/myvenv/lib/python3.10/site-packages/rest_framework/views.py", line 506, in dispatch
    response = handler(request, *args, **kwargs)
  File "/home/mydjangoproject/myfiles/alertlog/views.py", line 147, in get
    filterlogs = filterlogs.filter(timestamp__range(time1,time2))
NameError: name 'timestamp__range' is not defined
Internal Server Error: /filter/
Traceback (most recent call last):
  File "/home/mydjangoproject/myfiles/myvenv/lib/python3.10/site-packages/asgiref/sync.py", line 534, in thread_handler
    raise exc_info[1]
  File "/home/mydjangoproject/myfiles/myvenv/lib/python3.10/site-packages/django/core/handlers/exception.py", line 42, in inner
    response = await get_response(request)
  File "/home/mydjangoproject/myfiles/myvenv/lib/python3.10/site-packages/django/core/handlers/base.py", line 253, in _get_response_async
    response = await wrapped_callback(
  File "/home/mydjangoproject/myfiles/myvenv/lib/python3.10/site-packages/asgiref/sync.py", line 479, in __call__
    ret: _R = await loop.run_in_executor(
  File "/usr/lib/python3.10/concurrent/futures/thread.py", line 58, in run
    result = self.fn(*self.args, **self.kwargs)
  File "/home/mydjangoproject/myfiles/myvenv/lib/python3.10/site-packages/asgiref/sync.py", line 538, in thread_handler
    return func(*args, **kwargs)
  File "/home/mydjangoproject/myfiles/myvenv/lib/python3.10/site-packages/django/views/decorators/csrf.py", line 54, in wrapped_view
    return view_func(*args, **kwargs)
  File "/home/mydjangoproject/myfiles/myvenv/lib/python3.10/site-packages/django/views/generic/base.py", line 84, in view
    return self.dispatch(request, *args, **kwargs)
  File "/home/mydjangoproject/myfiles/myvenv/lib/python3.10/site-packages/rest_framework/views.py", line 509, in dispatch
    response = self.handle_exception(exc)
  File "/home/mydjangoproject/myfiles/myvenv/lib/python3.10/site-packages/rest_framework/views.py", line 469, in handle_exception
    self.raise_uncaught_exception(exc)
  File "/home/mydjangoproject/myfiles/myvenv/lib/python3.10/site-packages/rest_framework/views.py", line 480, in raise_uncaught_exception
    raise exc
  File "/home/mydjangoproject/myfiles/myvenv/lib/python3.10/site-packages/rest_framework/views.py", line 506, in dispatch
    response = handler(request, *args, **kwargs)
  File "/home/mydjangoproject/myfiles/alertlog/views.py", line 148, in get
    filterlogs = filterlogs.filter(timestamp__range(time1,time2))
NameError: name 'timestamp__range' is not defined
Internal Server Error: /filter/
Traceback (most recent call last):
  File "/home/mydjangoproject/myfiles/myvenv/lib/python3.10/site-packages/asgiref/sync.py", line 534, in thread_handler
    raise exc_info[1]
  File "/home/mydjangoproject/myfiles/myvenv/lib/python3.10/site-packages/django/core/handlers/exception.py", line 42, in inner
    response = await get_response(request)
  File "/home/mydjangoproject/myfiles/myvenv/lib/python3.10/site-packages/django/core/handlers/base.py", line 253, in _get_response_async
    response = await wrapped_callback(
  File "/home/mydjangoproject/myfiles/myvenv/lib/python3.10/site-packages/asgiref/sync.py", line 479, in __call__
    ret: _R = await loop.run_in_executor(
  File "/usr/lib/python3.10/concurrent/futures/thread.py", line 58, in run
    result = self.fn(*self.args, **self.kwargs)
  File "/home/mydjangoproject/myfiles/myvenv/lib/python3.10/site-packages/asgiref/sync.py", line 538, in thread_handler
    return func(*args, **kwargs)
  File "/home/mydjangoproject/myfiles/myvenv/lib/python3.10/site-packages/django/views/decorators/csrf.py", line 54, in wrapped_view
    return view_func(*args, **kwargs)
  File "/home/mydjangoproject/myfiles/myvenv/lib/python3.10/site-packages/django/views/generic/base.py", line 84, in view
    return self.dispatch(request, *args, **kwargs)
  File "/home/mydjangoproject/myfiles/myvenv/lib/python3.10/site-packages/rest_framework/views.py", line 509, in dispatch
    response = self.handle_exception(exc)
  File "/home/mydjangoproject/myfiles/myvenv/lib/python3.10/site-packages/rest_framework/views.py", line 469, in handle_exception
    self.raise_uncaught_exception(exc)
  File "/home/mydjangoproject/myfiles/myvenv/lib/python3.10/site-packages/rest_framework/views.py", line 480, in raise_uncaught_exception
    raise exc
  File "/home/mydjangoproject/myfiles/myvenv/lib/python3.10/site-packages/rest_framework/views.py", line 506, in dispatch
    response = handler(request, *args, **kwargs)
  File "/home/mydjangoproject/myfiles/alertlog/views.py", line 148, in get
    filterlogs = filterlogs.filter(timestamp__range=(time1, time2))
  File "/home/mydjangoproject/myfiles/myvenv/lib/python3.10/site-packages/django/db/models/query.py", line 1071, in filter
    return self._filter_or_exclude(False, args, kwargs)
  File "/home/mydjangoproject/myfiles/myvenv/lib/python3.10/site-packages/django/db/models/query.py", line 1089, in _filter_or_exclude
    clone._filter_or_exclude_inplace(negate, args, kwargs)
  File "/home/mydjangoproject/myfiles/myvenv/lib/python3.10/site-packages/django/db/models/query.py", line 1096, in _filter_or_exclude_inplace
    self._query.add_q(Q(*args, **kwargs))
  File "/home/mydjangoproject/myfiles/myvenv/lib/python3.10/site-packages/django/db/models/sql/query.py", line 1502, in add_q
    clause, _ = self._add_q(q_object, self.used_aliases)
  File "/home/mydjangoproject/myfiles/myvenv/lib/python3.10/site-packages/django/db/models/sql/query.py", line 1532, in _add_q
    child_clause, needed_inner = self.build_filter(
  File "/home/mydjangoproject/myfiles/myvenv/lib/python3.10/site-packages/django/db/models/sql/query.py", line 1448, in build_filter
    condition = self.build_lookup(lookups, col, value)
  File "/home/mydjangoproject/myfiles/myvenv/lib/python3.10/site-packages/django/db/models/sql/query.py", line 1273, in build_lookup
    lookup = lookup_class(lhs, rhs)
  File "/home/mydjangoproject/myfiles/myvenv/lib/python3.10/site-packages/django/db/models/lookups.py", line 27, in __init__
    self.rhs = self.get_prep_lookup()
  File "/home/mydjangoproject/myfiles/myvenv/lib/python3.10/site-packages/django/db/models/lookups.py", line 276, in get_prep_lookup
    rhs_value = self.lhs.output_field.get_prep_value(rhs_value)
  File "/home/mydjangoproject/myfiles/myvenv/lib/python3.10/site-packages/django/db/models/fields/__init__.py", line 1524, in get_prep_value
    value = super().get_prep_value(value)
  File "/home/mydjangoproject/myfiles/myvenv/lib/python3.10/site-packages/django/db/models/fields/__init__.py", line 1403, in get_prep_value
    return self.to_python(value)
  File "/home/mydjangoproject/myfiles/myvenv/lib/python3.10/site-packages/django/db/models/fields/__init__.py", line 1506, in to_python
    raise exceptions.ValidationError(
django.core.exceptions.ValidationError: ['“09/09/2023 15:38:03” value has an invalid format. It must be in YYYY-MM-DD HH:MM[:ss[.uuuuuu]][TZ] format.']
Internal Server Error: /admin/alertlog/roles/37/change/
Traceback (most recent call last):
  File "/home/mydjangoproject/myfiles/myvenv/lib/python3.10/site-packages/django/db/backends/utils.py", line 89, in _execute
    return self.cursor.execute(sql, params)
  File "/home/mydjangoproject/myfiles/myvenv/lib/python3.10/site-packages/django/db/backends/mysql/base.py", line 75, in execute
    return self.cursor.execute(query, args)
  File "/home/mydjangoproject/myfiles/myvenv/lib/python3.10/site-packages/MySQLdb/cursors.py", line 179, in execute
    res = self._query(mogrified_query)
  File "/home/mydjangoproject/myfiles/myvenv/lib/python3.10/site-packages/MySQLdb/cursors.py", line 330, in _query
    db.query(q)
  File "/home/mydjangoproject/myfiles/myvenv/lib/python3.10/site-packages/MySQLdb/connections.py", line 255, in query
    _mysql.connection.query(self, query)
MySQLdb.ProgrammingError: (1146, "Table 'Alertsystem.alertlog_roles' doesn't exist")

The above exception was the direct cause of the following exception:

Traceback (most recent call last):
  File "/home/mydjangoproject/myfiles/myvenv/lib/python3.10/site-packages/asgiref/sync.py", line 534, in thread_handler
    raise exc_info[1]
  File "/home/mydjangoproject/myfiles/myvenv/lib/python3.10/site-packages/django/core/handlers/exception.py", line 42, in inner
    response = await get_response(request)
  File "/home/mydjangoproject/myfiles/myvenv/lib/python3.10/site-packages/django/core/handlers/base.py", line 253, in _get_response_async
    response = await wrapped_callback(
  File "/home/mydjangoproject/myfiles/myvenv/lib/python3.10/site-packages/asgiref/sync.py", line 479, in __call__
    ret: _R = await loop.run_in_executor(
  File "/usr/lib/python3.10/concurrent/futures/thread.py", line 58, in run
    result = self.fn(*self.args, **self.kwargs)
  File "/home/mydjangoproject/myfiles/myvenv/lib/python3.10/site-packages/asgiref/sync.py", line 538, in thread_handler
    return func(*args, **kwargs)
  File "/home/mydjangoproject/myfiles/myvenv/lib/python3.10/site-packages/django/contrib/admin/options.py", line 683, in wrapper
    return self.admin_site.admin_view(view)(*args, **kwargs)
  File "/home/mydjangoproject/myfiles/myvenv/lib/python3.10/site-packages/django/utils/decorators.py", line 133, in _wrapped_view
    response = view_func(request, *args, **kwargs)
  File "/home/mydjangoproject/myfiles/myvenv/lib/python3.10/site-packages/django/views/decorators/cache.py", line 62, in _wrapped_view_func
    response = view_func(request, *args, **kwargs)
  File "/home/mydjangoproject/myfiles/myvenv/lib/python3.10/site-packages/django/contrib/admin/sites.py", line 242, in inner
    return view(request, *args, **kwargs)
  File "/home/mydjangoproject/myfiles/myvenv/lib/python3.10/site-packages/django/contrib/admin/options.py", line 1888, in change_view
    return self.changeform_view(request, object_id, form_url, extra_context)
  File "/home/mydjangoproject/myfiles/myvenv/lib/python3.10/site-packages/django/utils/decorators.py", line 46, in _wrapper
    return bound_method(*args, **kwargs)
  File "/home/mydjangoproject/myfiles/myvenv/lib/python3.10/site-packages/django/utils/decorators.py", line 133, in _wrapped_view
    response = view_func(request, *args, **kwargs)
  File "/home/mydjangoproject/myfiles/myvenv/lib/python3.10/site-packages/django/contrib/admin/options.py", line 1745, in changeform_view
    return self._changeform_view(request, object_id, form_url, extra_context)
  File "/home/mydjangoproject/myfiles/myvenv/lib/python3.10/site-packages/django/contrib/admin/options.py", line 1768, in _changeform_view
    obj = self.get_object(request, unquote(object_id), to_field)
  File "/home/mydjangoproject/myfiles/myvenv/lib/python3.10/site-packages/django/contrib/admin/options.py", line 861, in get_object
    return queryset.get(**{field.name: object_id})
  File "/home/mydjangoproject/myfiles/myvenv/lib/python3.10/site-packages/django/db/models/query.py", line 492, in get
    num = len(clone)
  File "/home/mydjangoproject/myfiles/myvenv/lib/python3.10/site-packages/django/db/models/query.py", line 302, in __len__
    self._fetch_all()
  File "/home/mydjangoproject/myfiles/myvenv/lib/python3.10/site-packages/django/db/models/query.py", line 1507, in _fetch_all
    self._result_cache = list(self._iterable_class(self))
  File "/home/mydjangoproject/myfiles/myvenv/lib/python3.10/site-packages/django/db/models/query.py", line 57, in __iter__
    results = compiler.execute_sql(
  File "/home/mydjangoproject/myfiles/myvenv/lib/python3.10/site-packages/django/db/models/sql/compiler.py", line 1361, in execute_sql
    cursor.execute(sql, params)
  File "/home/mydjangoproject/myfiles/myvenv/lib/python3.10/site-packages/django/db/backends/utils.py", line 103, in execute
    return super().execute(sql, params)
  File "/home/mydjangoproject/myfiles/myvenv/lib/python3.10/site-packages/django/db/backends/utils.py", line 67, in execute
    return self._execute_with_wrappers(
  File "/home/mydjangoproject/myfiles/myvenv/lib/python3.10/site-packages/django/db/backends/utils.py", line 80, in _execute_with_wrappers
    return executor(sql, params, many, context)
  File "/home/mydjangoproject/myfiles/myvenv/lib/python3.10/site-packages/django/db/backends/utils.py", line 84, in _execute
    with self.db.wrap_database_errors:
  File "/home/mydjangoproject/myfiles/myvenv/lib/python3.10/site-packages/django/db/utils.py", line 91, in __exit__
    raise dj_exc_value.with_traceback(traceback) from exc_value
  File "/home/mydjangoproject/myfiles/myvenv/lib/python3.10/site-packages/django/db/backends/utils.py", line 89, in _execute
    return self.cursor.execute(sql, params)
  File "/home/mydjangoproject/myfiles/myvenv/lib/python3.10/site-packages/django/db/backends/mysql/base.py", line 75, in execute
    return self.cursor.execute(query, args)
  File "/home/mydjangoproject/myfiles/myvenv/lib/python3.10/site-packages/MySQLdb/cursors.py", line 179, in execute
    res = self._query(mogrified_query)
  File "/home/mydjangoproject/myfiles/myvenv/lib/python3.10/site-packages/MySQLdb/cursors.py", line 330, in _query
    db.query(q)
  File "/home/mydjangoproject/myfiles/myvenv/lib/python3.10/site-packages/MySQLdb/connections.py", line 255, in query
    _mysql.connection.query(self, query)
django.db.utils.ProgrammingError: (1146, "Table 'Alertsystem.alertlog_roles' doesn't exist")
Internal Server Error: /admin/alertlog/filterlog/
Traceback (most recent call last):
  File "/home/mydjangoproject/myfiles/myvenv/lib/python3.10/site-packages/django/db/backends/utils.py", line 89, in _execute
    return self.cursor.execute(sql, params)
  File "/home/mydjangoproject/myfiles/myvenv/lib/python3.10/site-packages/django/db/backends/mysql/base.py", line 75, in execute
    return self.cursor.execute(query, args)
  File "/home/mydjangoproject/myfiles/myvenv/lib/python3.10/site-packages/MySQLdb/cursors.py", line 179, in execute
    res = self._query(mogrified_query)
  File "/home/mydjangoproject/myfiles/myvenv/lib/python3.10/site-packages/MySQLdb/cursors.py", line 330, in _query
    db.query(q)
  File "/home/mydjangoproject/myfiles/myvenv/lib/python3.10/site-packages/MySQLdb/connections.py", line 255, in query
    _mysql.connection.query(self, query)
MySQLdb.ProgrammingError: (1146, "Table 'Alertsystem.alertlog_filterlog' doesn't exist")

The above exception was the direct cause of the following exception:

Traceback (most recent call last):
  File "/home/mydjangoproject/myfiles/myvenv/lib/python3.10/site-packages/asgiref/sync.py", line 534, in thread_handler
    raise exc_info[1]
  File "/home/mydjangoproject/myfiles/myvenv/lib/python3.10/site-packages/django/core/handlers/exception.py", line 42, in inner
    response = await get_response(request)
  File "/home/mydjangoproject/myfiles/myvenv/lib/python3.10/site-packages/django/core/handlers/base.py", line 253, in _get_response_async
    response = await wrapped_callback(
  File "/home/mydjangoproject/myfiles/myvenv/lib/python3.10/site-packages/asgiref/sync.py", line 479, in __call__
    ret: _R = await loop.run_in_executor(
  File "/usr/lib/python3.10/concurrent/futures/thread.py", line 58, in run
    result = self.fn(*self.args, **self.kwargs)
  File "/home/mydjangoproject/myfiles/myvenv/lib/python3.10/site-packages/asgiref/sync.py", line 538, in thread_handler
    return func(*args, **kwargs)
  File "/home/mydjangoproject/myfiles/myvenv/lib/python3.10/site-packages/django/contrib/admin/options.py", line 683, in wrapper
    return self.admin_site.admin_view(view)(*args, **kwargs)
  File "/home/mydjangoproject/myfiles/myvenv/lib/python3.10/site-packages/django/utils/decorators.py", line 133, in _wrapped_view
    response = view_func(request, *args, **kwargs)
  File "/home/mydjangoproject/myfiles/myvenv/lib/python3.10/site-packages/django/views/decorators/cache.py", line 62, in _wrapped_view_func
    response = view_func(request, *args, **kwargs)
  File "/home/mydjangoproject/myfiles/myvenv/lib/python3.10/site-packages/django/contrib/admin/sites.py", line 242, in inner
    return view(request, *args, **kwargs)
  File "/home/mydjangoproject/myfiles/myvenv/lib/python3.10/site-packages/django/utils/decorators.py", line 46, in _wrapper
    return bound_method(*args, **kwargs)
  File "/home/mydjangoproject/myfiles/myvenv/lib/python3.10/site-packages/django/utils/decorators.py", line 133, in _wrapped_view
    response = view_func(request, *args, **kwargs)
  File "/home/mydjangoproject/myfiles/myvenv/lib/python3.10/site-packages/django/contrib/admin/options.py", line 1926, in changelist_view
    cl = self.get_changelist_instance(request)
  File "/home/mydjangoproject/myfiles/myvenv/lib/python3.10/site-packages/django/contrib/admin/options.py", line 831, in get_changelist_instance
    return ChangeList(
  File "/home/mydjangoproject/myfiles/myvenv/lib/python3.10/site-packages/django/contrib/admin/views/main.py", line 123, in __init__
    self.get_results(request)
  File "/home/mydjangoproject/myfiles/myvenv/lib/python3.10/site-packages/django/contrib/admin/views/main.py", line 279, in get_results
    result_count = paginator.count
  File "/home/mydjangoproject/myfiles/myvenv/lib/python3.10/site-packages/django/utils/functional.py", line 49, in __get__
    res = instance.__dict__[self.name] = self.func(instance)
  File "/home/mydjangoproject/myfiles/myvenv/lib/python3.10/site-packages/django/core/paginator.py", line 96, in count
    return c()
  File "/home/mydjangoproject/myfiles/myvenv/lib/python3.10/site-packages/django/db/models/query.py", line 470, in count
    return self.query.get_count(using=self.db)
  File "/home/mydjangoproject/myfiles/myvenv/lib/python3.10/site-packages/django/db/models/sql/query.py", line 552, in get_count
    number = obj.get_aggregation(using, ["__count"])["__count"]
  File "/home/mydjangoproject/myfiles/myvenv/lib/python3.10/site-packages/django/db/models/sql/query.py", line 537, in get_aggregation
    result = compiler.execute_sql(SINGLE)
  File "/home/mydjangoproject/myfiles/myvenv/lib/python3.10/site-packages/django/db/models/sql/compiler.py", line 1361, in execute_sql
    cursor.execute(sql, params)
  File "/home/mydjangoproject/myfiles/myvenv/lib/python3.10/site-packages/django/db/backends/utils.py", line 103, in execute
    return super().execute(sql, params)
  File "/home/mydjangoproject/myfiles/myvenv/lib/python3.10/site-packages/django/db/backends/utils.py", line 67, in execute
    return self._execute_with_wrappers(
  File "/home/mydjangoproject/myfiles/myvenv/lib/python3.10/site-packages/django/db/backends/utils.py", line 80, in _execute_with_wrappers
    return executor(sql, params, many, context)
  File "/home/mydjangoproject/myfiles/myvenv/lib/python3.10/site-packages/django/db/backends/utils.py", line 84, in _execute
    with self.db.wrap_database_errors:
  File "/home/mydjangoproject/myfiles/myvenv/lib/python3.10/site-packages/django/db/utils.py", line 91, in __exit__
    raise dj_exc_value.with_traceback(traceback) from exc_value
  File "/home/mydjangoproject/myfiles/myvenv/lib/python3.10/site-packages/django/db/backends/utils.py", line 89, in _execute
    return self.cursor.execute(sql, params)
  File "/home/mydjangoproject/myfiles/myvenv/lib/python3.10/site-packages/django/db/backends/mysql/base.py", line 75, in execute
    return self.cursor.execute(query, args)
  File "/home/mydjangoproject/myfiles/myvenv/lib/python3.10/site-packages/MySQLdb/cursors.py", line 179, in execute
    res = self._query(mogrified_query)
  File "/home/mydjangoproject/myfiles/myvenv/lib/python3.10/site-packages/MySQLdb/cursors.py", line 330, in _query
    db.query(q)
  File "/home/mydjangoproject/myfiles/myvenv/lib/python3.10/site-packages/MySQLdb/connections.py", line 255, in query
    _mysql.connection.query(self, query)
django.db.utils.ProgrammingError: (1146, "Table 'Alertsystem.alertlog_filterlog' doesn't exist")
Internal Server Error: /admin/alertlog/filterlog/
Traceback (most recent call last):
  File "/home/mydjangoproject/myfiles/myvenv/lib/python3.10/site-packages/django/db/backends/utils.py", line 89, in _execute
    return self.cursor.execute(sql, params)
  File "/home/mydjangoproject/myfiles/myvenv/lib/python3.10/site-packages/django/db/backends/mysql/base.py", line 75, in execute
    return self.cursor.execute(query, args)
  File "/home/mydjangoproject/myfiles/myvenv/lib/python3.10/site-packages/MySQLdb/cursors.py", line 179, in execute
    res = self._query(mogrified_query)
  File "/home/mydjangoproject/myfiles/myvenv/lib/python3.10/site-packages/MySQLdb/cursors.py", line 330, in _query
    db.query(q)
  File "/home/mydjangoproject/myfiles/myvenv/lib/python3.10/site-packages/MySQLdb/connections.py", line 255, in query
    _mysql.connection.query(self, query)
MySQLdb.ProgrammingError: (1146, "Table 'Alertsystem.alertlog_filterlog' doesn't exist")

The above exception was the direct cause of the following exception:

Traceback (most recent call last):
  File "/home/mydjangoproject/myfiles/myvenv/lib/python3.10/site-packages/asgiref/sync.py", line 534, in thread_handler
    raise exc_info[1]
  File "/home/mydjangoproject/myfiles/myvenv/lib/python3.10/site-packages/django/core/handlers/exception.py", line 42, in inner
    response = await get_response(request)
  File "/home/mydjangoproject/myfiles/myvenv/lib/python3.10/site-packages/django/core/handlers/base.py", line 253, in _get_response_async
    response = await wrapped_callback(
  File "/home/mydjangoproject/myfiles/myvenv/lib/python3.10/site-packages/asgiref/sync.py", line 479, in __call__
    ret: _R = await loop.run_in_executor(
  File "/usr/lib/python3.10/concurrent/futures/thread.py", line 58, in run
    result = self.fn(*self.args, **self.kwargs)
  File "/home/mydjangoproject/myfiles/myvenv/lib/python3.10/site-packages/asgiref/sync.py", line 538, in thread_handler
    return func(*args, **kwargs)
  File "/home/mydjangoproject/myfiles/myvenv/lib/python3.10/site-packages/django/contrib/admin/options.py", line 683, in wrapper
    return self.admin_site.admin_view(view)(*args, **kwargs)
  File "/home/mydjangoproject/myfiles/myvenv/lib/python3.10/site-packages/django/utils/decorators.py", line 133, in _wrapped_view
    response = view_func(request, *args, **kwargs)
  File "/home/mydjangoproject/myfiles/myvenv/lib/python3.10/site-packages/django/views/decorators/cache.py", line 62, in _wrapped_view_func
    response = view_func(request, *args, **kwargs)
  File "/home/mydjangoproject/myfiles/myvenv/lib/python3.10/site-packages/django/contrib/admin/sites.py", line 242, in inner
    return view(request, *args, **kwargs)
  File "/home/mydjangoproject/myfiles/myvenv/lib/python3.10/site-packages/django/utils/decorators.py", line 46, in _wrapper
    return bound_method(*args, **kwargs)
  File "/home/mydjangoproject/myfiles/myvenv/lib/python3.10/site-packages/django/utils/decorators.py", line 133, in _wrapped_view
    response = view_func(request, *args, **kwargs)
  File "/home/mydjangoproject/myfiles/myvenv/lib/python3.10/site-packages/django/contrib/admin/options.py", line 1926, in changelist_view
    cl = self.get_changelist_instance(request)
  File "/home/mydjangoproject/myfiles/myvenv/lib/python3.10/site-packages/django/contrib/admin/options.py", line 831, in get_changelist_instance
    return ChangeList(
  File "/home/mydjangoproject/myfiles/myvenv/lib/python3.10/site-packages/django/contrib/admin/views/main.py", line 123, in __init__
    self.get_results(request)
  File "/home/mydjangoproject/myfiles/myvenv/lib/python3.10/site-packages/django/contrib/admin/views/main.py", line 279, in get_results
    result_count = paginator.count
  File "/home/mydjangoproject/myfiles/myvenv/lib/python3.10/site-packages/django/utils/functional.py", line 49, in __get__
    res = instance.__dict__[self.name] = self.func(instance)
  File "/home/mydjangoproject/myfiles/myvenv/lib/python3.10/site-packages/django/core/paginator.py", line 96, in count
    return c()
  File "/home/mydjangoproject/myfiles/myvenv/lib/python3.10/site-packages/django/db/models/query.py", line 470, in count
    return self.query.get_count(using=self.db)
  File "/home/mydjangoproject/myfiles/myvenv/lib/python3.10/site-packages/django/db/models/sql/query.py", line 552, in get_count
    number = obj.get_aggregation(using, ["__count"])["__count"]
  File "/home/mydjangoproject/myfiles/myvenv/lib/python3.10/site-packages/django/db/models/sql/query.py", line 537, in get_aggregation
    result = compiler.execute_sql(SINGLE)
  File "/home/mydjangoproject/myfiles/myvenv/lib/python3.10/site-packages/django/db/models/sql/compiler.py", line 1361, in execute_sql
    cursor.execute(sql, params)
  File "/home/mydjangoproject/myfiles/myvenv/lib/python3.10/site-packages/django/db/backends/utils.py", line 103, in execute
    return super().execute(sql, params)
  File "/home/mydjangoproject/myfiles/myvenv/lib/python3.10/site-packages/django/db/backends/utils.py", line 67, in execute
    return self._execute_with_wrappers(
  File "/home/mydjangoproject/myfiles/myvenv/lib/python3.10/site-packages/django/db/backends/utils.py", line 80, in _execute_with_wrappers
    return executor(sql, params, many, context)
  File "/home/mydjangoproject/myfiles/myvenv/lib/python3.10/site-packages/django/db/backends/utils.py", line 84, in _execute
    with self.db.wrap_database_errors:
  File "/home/mydjangoproject/myfiles/myvenv/lib/python3.10/site-packages/django/db/utils.py", line 91, in __exit__
    raise dj_exc_value.with_traceback(traceback) from exc_value
  File "/home/mydjangoproject/myfiles/myvenv/lib/python3.10/site-packages/django/db/backends/utils.py", line 89, in _execute
    return self.cursor.execute(sql, params)
  File "/home/mydjangoproject/myfiles/myvenv/lib/python3.10/site-packages/django/db/backends/mysql/base.py", line 75, in execute
    return self.cursor.execute(query, args)
  File "/home/mydjangoproject/myfiles/myvenv/lib/python3.10/site-packages/MySQLdb/cursors.py", line 179, in execute
    res = self._query(mogrified_query)
  File "/home/mydjangoproject/myfiles/myvenv/lib/python3.10/site-packages/MySQLdb/cursors.py", line 330, in _query
    db.query(q)
  File "/home/mydjangoproject/myfiles/myvenv/lib/python3.10/site-packages/MySQLdb/connections.py", line 255, in query
    _mysql.connection.query(self, query)
django.db.utils.ProgrammingError: (1146, "Table 'Alertsystem.alertlog_filterlog' doesn't exist")
Internal Server Error: /admin/alertlog/hostnames/
Traceback (most recent call last):
  File "/home/mydjangoproject/myfiles/myvenv/lib/python3.10/site-packages/django/db/backends/utils.py", line 89, in _execute
    return self.cursor.execute(sql, params)
  File "/home/mydjangoproject/myfiles/myvenv/lib/python3.10/site-packages/django/db/backends/mysql/base.py", line 75, in execute
    return self.cursor.execute(query, args)
  File "/home/mydjangoproject/myfiles/myvenv/lib/python3.10/site-packages/MySQLdb/cursors.py", line 179, in execute
    res = self._query(mogrified_query)
  File "/home/mydjangoproject/myfiles/myvenv/lib/python3.10/site-packages/MySQLdb/cursors.py", line 330, in _query
    db.query(q)
  File "/home/mydjangoproject/myfiles/myvenv/lib/python3.10/site-packages/MySQLdb/connections.py", line 255, in query
    _mysql.connection.query(self, query)
MySQLdb.ProgrammingError: (1146, "Table 'Alertsystem.alertlog_hostnames' doesn't exist")

The above exception was the direct cause of the following exception:

Traceback (most recent call last):
  File "/home/mydjangoproject/myfiles/myvenv/lib/python3.10/site-packages/asgiref/sync.py", line 534, in thread_handler
    raise exc_info[1]
  File "/home/mydjangoproject/myfiles/myvenv/lib/python3.10/site-packages/django/core/handlers/exception.py", line 42, in inner
    response = await get_response(request)
  File "/home/mydjangoproject/myfiles/myvenv/lib/python3.10/site-packages/django/core/handlers/base.py", line 253, in _get_response_async
    response = await wrapped_callback(
  File "/home/mydjangoproject/myfiles/myvenv/lib/python3.10/site-packages/asgiref/sync.py", line 479, in __call__
    ret: _R = await loop.run_in_executor(
  File "/usr/lib/python3.10/concurrent/futures/thread.py", line 58, in run
    result = self.fn(*self.args, **self.kwargs)
  File "/home/mydjangoproject/myfiles/myvenv/lib/python3.10/site-packages/asgiref/sync.py", line 538, in thread_handler
    return func(*args, **kwargs)
  File "/home/mydjangoproject/myfiles/myvenv/lib/python3.10/site-packages/django/contrib/admin/options.py", line 683, in wrapper
    return self.admin_site.admin_view(view)(*args, **kwargs)
  File "/home/mydjangoproject/myfiles/myvenv/lib/python3.10/site-packages/django/utils/decorators.py", line 133, in _wrapped_view
    response = view_func(request, *args, **kwargs)
  File "/home/mydjangoproject/myfiles/myvenv/lib/python3.10/site-packages/django/views/decorators/cache.py", line 62, in _wrapped_view_func
    response = view_func(request, *args, **kwargs)
  File "/home/mydjangoproject/myfiles/myvenv/lib/python3.10/site-packages/django/contrib/admin/sites.py", line 242, in inner
    return view(request, *args, **kwargs)
  File "/home/mydjangoproject/myfiles/myvenv/lib/python3.10/site-packages/django/utils/decorators.py", line 46, in _wrapper
    return bound_method(*args, **kwargs)
  File "/home/mydjangoproject/myfiles/myvenv/lib/python3.10/site-packages/django/utils/decorators.py", line 133, in _wrapped_view
    response = view_func(request, *args, **kwargs)
  File "/home/mydjangoproject/myfiles/myvenv/lib/python3.10/site-packages/django/contrib/admin/options.py", line 1926, in changelist_view
    cl = self.get_changelist_instance(request)
  File "/home/mydjangoproject/myfiles/myvenv/lib/python3.10/site-packages/django/contrib/admin/options.py", line 831, in get_changelist_instance
    return ChangeList(
  File "/home/mydjangoproject/myfiles/myvenv/lib/python3.10/site-packages/django/contrib/admin/views/main.py", line 123, in __init__
    self.get_results(request)
  File "/home/mydjangoproject/myfiles/myvenv/lib/python3.10/site-packages/django/contrib/admin/views/main.py", line 279, in get_results
    result_count = paginator.count
  File "/home/mydjangoproject/myfiles/myvenv/lib/python3.10/site-packages/django/utils/functional.py", line 49, in __get__
    res = instance.__dict__[self.name] = self.func(instance)
  File "/home/mydjangoproject/myfiles/myvenv/lib/python3.10/site-packages/django/core/paginator.py", line 96, in count
    return c()
  File "/home/mydjangoproject/myfiles/myvenv/lib/python3.10/site-packages/django/db/models/query.py", line 470, in count
    return self.query.get_count(using=self.db)
  File "/home/mydjangoproject/myfiles/myvenv/lib/python3.10/site-packages/django/db/models/sql/query.py", line 552, in get_count
    number = obj.get_aggregation(using, ["__count"])["__count"]
  File "/home/mydjangoproject/myfiles/myvenv/lib/python3.10/site-packages/django/db/models/sql/query.py", line 537, in get_aggregation
    result = compiler.execute_sql(SINGLE)
  File "/home/mydjangoproject/myfiles/myvenv/lib/python3.10/site-packages/django/db/models/sql/compiler.py", line 1361, in execute_sql
    cursor.execute(sql, params)
  File "/home/mydjangoproject/myfiles/myvenv/lib/python3.10/site-packages/django/db/backends/utils.py", line 103, in execute
    return super().execute(sql, params)
  File "/home/mydjangoproject/myfiles/myvenv/lib/python3.10/site-packages/django/db/backends/utils.py", line 67, in execute
    return self._execute_with_wrappers(
  File "/home/mydjangoproject/myfiles/myvenv/lib/python3.10/site-packages/django/db/backends/utils.py", line 80, in _execute_with_wrappers
    return executor(sql, params, many, context)
  File "/home/mydjangoproject/myfiles/myvenv/lib/python3.10/site-packages/django/db/backends/utils.py", line 84, in _execute
    with self.db.wrap_database_errors:
  File "/home/mydjangoproject/myfiles/myvenv/lib/python3.10/site-packages/django/db/utils.py", line 91, in __exit__
    raise dj_exc_value.with_traceback(traceback) from exc_value
  File "/home/mydjangoproject/myfiles/myvenv/lib/python3.10/site-packages/django/db/backends/utils.py", line 89, in _execute
    return self.cursor.execute(sql, params)
  File "/home/mydjangoproject/myfiles/myvenv/lib/python3.10/site-packages/django/db/backends/mysql/base.py", line 75, in execute
    return self.cursor.execute(query, args)
  File "/home/mydjangoproject/myfiles/myvenv/lib/python3.10/site-packages/MySQLdb/cursors.py", line 179, in execute
    res = self._query(mogrified_query)
  File "/home/mydjangoproject/myfiles/myvenv/lib/python3.10/site-packages/MySQLdb/cursors.py", line 330, in _query
    db.query(q)
  File "/home/mydjangoproject/myfiles/myvenv/lib/python3.10/site-packages/MySQLdb/connections.py", line 255, in query
    _mysql.connection.query(self, query)
django.db.utils.ProgrammingError: (1146, "Table 'Alertsystem.alertlog_hostnames' doesn't exist")
Internal Server Error: /admin/alertlog/hostnames/
Traceback (most recent call last):
  File "/home/mydjangoproject/myfiles/myvenv/lib/python3.10/site-packages/django/db/backends/utils.py", line 89, in _execute
    return self.cursor.execute(sql, params)
  File "/home/mydjangoproject/myfiles/myvenv/lib/python3.10/site-packages/django/db/backends/mysql/base.py", line 75, in execute
    return self.cursor.execute(query, args)
  File "/home/mydjangoproject/myfiles/myvenv/lib/python3.10/site-packages/MySQLdb/cursors.py", line 179, in execute
    res = self._query(mogrified_query)
  File "/home/mydjangoproject/myfiles/myvenv/lib/python3.10/site-packages/MySQLdb/cursors.py", line 330, in _query
    db.query(q)
  File "/home/mydjangoproject/myfiles/myvenv/lib/python3.10/site-packages/MySQLdb/connections.py", line 255, in query
    _mysql.connection.query(self, query)
MySQLdb.ProgrammingError: (1146, "Table 'Alertsystem.alertlog_hostnames' doesn't exist")

The above exception was the direct cause of the following exception:

Traceback (most recent call last):
  File "/home/mydjangoproject/myfiles/myvenv/lib/python3.10/site-packages/asgiref/sync.py", line 534, in thread_handler
    raise exc_info[1]
  File "/home/mydjangoproject/myfiles/myvenv/lib/python3.10/site-packages/django/core/handlers/exception.py", line 42, in inner
    response = await get_response(request)
  File "/home/mydjangoproject/myfiles/myvenv/lib/python3.10/site-packages/django/core/handlers/base.py", line 253, in _get_response_async
    response = await wrapped_callback(
  File "/home/mydjangoproject/myfiles/myvenv/lib/python3.10/site-packages/asgiref/sync.py", line 479, in __call__
    ret: _R = await loop.run_in_executor(
  File "/usr/lib/python3.10/concurrent/futures/thread.py", line 58, in run
    result = self.fn(*self.args, **self.kwargs)
  File "/home/mydjangoproject/myfiles/myvenv/lib/python3.10/site-packages/asgiref/sync.py", line 538, in thread_handler
    return func(*args, **kwargs)
  File "/home/mydjangoproject/myfiles/myvenv/lib/python3.10/site-packages/django/contrib/admin/options.py", line 683, in wrapper
    return self.admin_site.admin_view(view)(*args, **kwargs)
  File "/home/mydjangoproject/myfiles/myvenv/lib/python3.10/site-packages/django/utils/decorators.py", line 133, in _wrapped_view
    response = view_func(request, *args, **kwargs)
  File "/home/mydjangoproject/myfiles/myvenv/lib/python3.10/site-packages/django/views/decorators/cache.py", line 62, in _wrapped_view_func
    response = view_func(request, *args, **kwargs)
  File "/home/mydjangoproject/myfiles/myvenv/lib/python3.10/site-packages/django/contrib/admin/sites.py", line 242, in inner
    return view(request, *args, **kwargs)
  File "/home/mydjangoproject/myfiles/myvenv/lib/python3.10/site-packages/django/utils/decorators.py", line 46, in _wrapper
    return bound_method(*args, **kwargs)
  File "/home/mydjangoproject/myfiles/myvenv/lib/python3.10/site-packages/django/utils/decorators.py", line 133, in _wrapped_view
    response = view_func(request, *args, **kwargs)
  File "/home/mydjangoproject/myfiles/myvenv/lib/python3.10/site-packages/django/contrib/admin/options.py", line 1926, in changelist_view
    cl = self.get_changelist_instance(request)
  File "/home/mydjangoproject/myfiles/myvenv/lib/python3.10/site-packages/django/contrib/admin/options.py", line 831, in get_changelist_instance
    return ChangeList(
  File "/home/mydjangoproject/myfiles/myvenv/lib/python3.10/site-packages/django/contrib/admin/views/main.py", line 123, in __init__
    self.get_results(request)
  File "/home/mydjangoproject/myfiles/myvenv/lib/python3.10/site-packages/django/contrib/admin/views/main.py", line 279, in get_results
    result_count = paginator.count
  File "/home/mydjangoproject/myfiles/myvenv/lib/python3.10/site-packages/django/utils/functional.py", line 49, in __get__
    res = instance.__dict__[self.name] = self.func(instance)
  File "/home/mydjangoproject/myfiles/myvenv/lib/python3.10/site-packages/django/core/paginator.py", line 96, in count
    return c()
  File "/home/mydjangoproject/myfiles/myvenv/lib/python3.10/site-packages/django/db/models/query.py", line 470, in count
    return self.query.get_count(using=self.db)
  File "/home/mydjangoproject/myfiles/myvenv/lib/python3.10/site-packages/django/db/models/sql/query.py", line 552, in get_count
    number = obj.get_aggregation(using, ["__count"])["__count"]
  File "/home/mydjangoproject/myfiles/myvenv/lib/python3.10/site-packages/django/db/models/sql/query.py", line 537, in get_aggregation
    result = compiler.execute_sql(SINGLE)
  File "/home/mydjangoproject/myfiles/myvenv/lib/python3.10/site-packages/django/db/models/sql/compiler.py", line 1361, in execute_sql
    cursor.execute(sql, params)
  File "/home/mydjangoproject/myfiles/myvenv/lib/python3.10/site-packages/django/db/backends/utils.py", line 103, in execute
    return super().execute(sql, params)
  File "/home/mydjangoproject/myfiles/myvenv/lib/python3.10/site-packages/django/db/backends/utils.py", line 67, in execute
    return self._execute_with_wrappers(
  File "/home/mydjangoproject/myfiles/myvenv/lib/python3.10/site-packages/django/db/backends/utils.py", line 80, in _execute_with_wrappers
    return executor(sql, params, many, context)
  File "/home/mydjangoproject/myfiles/myvenv/lib/python3.10/site-packages/django/db/backends/utils.py", line 84, in _execute
    with self.db.wrap_database_errors:
  File "/home/mydjangoproject/myfiles/myvenv/lib/python3.10/site-packages/django/db/utils.py", line 91, in __exit__
    raise dj_exc_value.with_traceback(traceback) from exc_value
  File "/home/mydjangoproject/myfiles/myvenv/lib/python3.10/site-packages/django/db/backends/utils.py", line 89, in _execute
    return self.cursor.execute(sql, params)
  File "/home/mydjangoproject/myfiles/myvenv/lib/python3.10/site-packages/django/db/backends/mysql/base.py", line 75, in execute
    return self.cursor.execute(query, args)
  File "/home/mydjangoproject/myfiles/myvenv/lib/python3.10/site-packages/MySQLdb/cursors.py", line 179, in execute
    res = self._query(mogrified_query)
  File "/home/mydjangoproject/myfiles/myvenv/lib/python3.10/site-packages/MySQLdb/cursors.py", line 330, in _query
    db.query(q)
  File "/home/mydjangoproject/myfiles/myvenv/lib/python3.10/site-packages/MySQLdb/connections.py", line 255, in query
    _mysql.connection.query(self, query)
django.db.utils.ProgrammingError: (1146, "Table 'Alertsystem.alertlog_hostnames' doesn't exist")
Internal Server Error: /admin/alertlog/hostnames/
Traceback (most recent call last):
  File "/home/mydjangoproject/myfiles/myvenv/lib/python3.10/site-packages/django/db/backends/utils.py", line 89, in _execute
    return self.cursor.execute(sql, params)
  File "/home/mydjangoproject/myfiles/myvenv/lib/python3.10/site-packages/django/db/backends/mysql/base.py", line 75, in execute
    return self.cursor.execute(query, args)
  File "/home/mydjangoproject/myfiles/myvenv/lib/python3.10/site-packages/MySQLdb/cursors.py", line 179, in execute
    res = self._query(mogrified_query)
  File "/home/mydjangoproject/myfiles/myvenv/lib/python3.10/site-packages/MySQLdb/cursors.py", line 330, in _query
    db.query(q)
  File "/home/mydjangoproject/myfiles/myvenv/lib/python3.10/site-packages/MySQLdb/connections.py", line 255, in query
    _mysql.connection.query(self, query)
MySQLdb.ProgrammingError: (1146, "Table 'Alertsystem.alertlog_hostnames' doesn't exist")

The above exception was the direct cause of the following exception:

Traceback (most recent call last):
  File "/home/mydjangoproject/myfiles/myvenv/lib/python3.10/site-packages/asgiref/sync.py", line 534, in thread_handler
    raise exc_info[1]
  File "/home/mydjangoproject/myfiles/myvenv/lib/python3.10/site-packages/django/core/handlers/exception.py", line 42, in inner
    response = await get_response(request)
  File "/home/mydjangoproject/myfiles/myvenv/lib/python3.10/site-packages/django/core/handlers/base.py", line 253, in _get_response_async
    response = await wrapped_callback(
  File "/home/mydjangoproject/myfiles/myvenv/lib/python3.10/site-packages/asgiref/sync.py", line 479, in __call__
    ret: _R = await loop.run_in_executor(
  File "/usr/lib/python3.10/concurrent/futures/thread.py", line 58, in run
    result = self.fn(*self.args, **self.kwargs)
  File "/home/mydjangoproject/myfiles/myvenv/lib/python3.10/site-packages/asgiref/sync.py", line 538, in thread_handler
    return func(*args, **kwargs)
  File "/home/mydjangoproject/myfiles/myvenv/lib/python3.10/site-packages/django/contrib/admin/options.py", line 683, in wrapper
    return self.admin_site.admin_view(view)(*args, **kwargs)
  File "/home/mydjangoproject/myfiles/myvenv/lib/python3.10/site-packages/django/utils/decorators.py", line 133, in _wrapped_view
    response = view_func(request, *args, **kwargs)
  File "/home/mydjangoproject/myfiles/myvenv/lib/python3.10/site-packages/django/views/decorators/cache.py", line 62, in _wrapped_view_func
    response = view_func(request, *args, **kwargs)
  File "/home/mydjangoproject/myfiles/myvenv/lib/python3.10/site-packages/django/contrib/admin/sites.py", line 242, in inner
    return view(request, *args, **kwargs)
  File "/home/mydjangoproject/myfiles/myvenv/lib/python3.10/site-packages/django/utils/decorators.py", line 46, in _wrapper
    return bound_method(*args, **kwargs)
  File "/home/mydjangoproject/myfiles/myvenv/lib/python3.10/site-packages/django/utils/decorators.py", line 133, in _wrapped_view
    response = view_func(request, *args, **kwargs)
  File "/home/mydjangoproject/myfiles/myvenv/lib/python3.10/site-packages/django/contrib/admin/options.py", line 1926, in changelist_view
    cl = self.get_changelist_instance(request)
  File "/home/mydjangoproject/myfiles/myvenv/lib/python3.10/site-packages/django/contrib/admin/options.py", line 831, in get_changelist_instance
    return ChangeList(
  File "/home/mydjangoproject/myfiles/myvenv/lib/python3.10/site-packages/django/contrib/admin/views/main.py", line 123, in __init__
    self.get_results(request)
  File "/home/mydjangoproject/myfiles/myvenv/lib/python3.10/site-packages/django/contrib/admin/views/main.py", line 279, in get_results
    result_count = paginator.count
  File "/home/mydjangoproject/myfiles/myvenv/lib/python3.10/site-packages/django/utils/functional.py", line 49, in __get__
    res = instance.__dict__[self.name] = self.func(instance)
  File "/home/mydjangoproject/myfiles/myvenv/lib/python3.10/site-packages/django/core/paginator.py", line 96, in count
    return c()
  File "/home/mydjangoproject/myfiles/myvenv/lib/python3.10/site-packages/django/db/models/query.py", line 470, in count
    return self.query.get_count(using=self.db)
  File "/home/mydjangoproject/myfiles/myvenv/lib/python3.10/site-packages/django/db/models/sql/query.py", line 552, in get_count
    number = obj.get_aggregation(using, ["__count"])["__count"]
  File "/home/mydjangoproject/myfiles/myvenv/lib/python3.10/site-packages/django/db/models/sql/query.py", line 537, in get_aggregation
    result = compiler.execute_sql(SINGLE)
  File "/home/mydjangoproject/myfiles/myvenv/lib/python3.10/site-packages/django/db/models/sql/compiler.py", line 1361, in execute_sql
    cursor.execute(sql, params)
  File "/home/mydjangoproject/myfiles/myvenv/lib/python3.10/site-packages/django/db/backends/utils.py", line 103, in execute
    return super().execute(sql, params)
  File "/home/mydjangoproject/myfiles/myvenv/lib/python3.10/site-packages/django/db/backends/utils.py", line 67, in execute
    return self._execute_with_wrappers(
  File "/home/mydjangoproject/myfiles/myvenv/lib/python3.10/site-packages/django/db/backends/utils.py", line 80, in _execute_with_wrappers
    return executor(sql, params, many, context)
  File "/home/mydjangoproject/myfiles/myvenv/lib/python3.10/site-packages/django/db/backends/utils.py", line 84, in _execute
    with self.db.wrap_database_errors:
  File "/home/mydjangoproject/myfiles/myvenv/lib/python3.10/site-packages/django/db/utils.py", line 91, in __exit__
    raise dj_exc_value.with_traceback(traceback) from exc_value
  File "/home/mydjangoproject/myfiles/myvenv/lib/python3.10/site-packages/django/db/backends/utils.py", line 89, in _execute
    return self.cursor.execute(sql, params)
  File "/home/mydjangoproject/myfiles/myvenv/lib/python3.10/site-packages/django/db/backends/mysql/base.py", line 75, in execute
    return self.cursor.execute(query, args)
  File "/home/mydjangoproject/myfiles/myvenv/lib/python3.10/site-packages/MySQLdb/cursors.py", line 179, in execute
    res = self._query(mogrified_query)
  File "/home/mydjangoproject/myfiles/myvenv/lib/python3.10/site-packages/MySQLdb/cursors.py", line 330, in _query
    db.query(q)
  File "/home/mydjangoproject/myfiles/myvenv/lib/python3.10/site-packages/MySQLdb/connections.py", line 255, in query
    _mysql.connection.query(self, query)
django.db.utils.ProgrammingError: (1146, "Table 'Alertsystem.alertlog_hostnames' doesn't exist")
Internal Server Error: /admin/alertlog/roles/
Traceback (most recent call last):
  File "/home/mydjangoproject/myfiles/myvenv/lib/python3.10/site-packages/django/db/backends/utils.py", line 89, in _execute
    return self.cursor.execute(sql, params)
  File "/home/mydjangoproject/myfiles/myvenv/lib/python3.10/site-packages/django/db/backends/mysql/base.py", line 75, in execute
    return self.cursor.execute(query, args)
  File "/home/mydjangoproject/myfiles/myvenv/lib/python3.10/site-packages/MySQLdb/cursors.py", line 179, in execute
    res = self._query(mogrified_query)
  File "/home/mydjangoproject/myfiles/myvenv/lib/python3.10/site-packages/MySQLdb/cursors.py", line 330, in _query
    db.query(q)
  File "/home/mydjangoproject/myfiles/myvenv/lib/python3.10/site-packages/MySQLdb/connections.py", line 255, in query
    _mysql.connection.query(self, query)
MySQLdb.ProgrammingError: (1146, "Table 'Alertsystem.alertlog_roles' doesn't exist")

The above exception was the direct cause of the following exception:

Traceback (most recent call last):
  File "/home/mydjangoproject/myfiles/myvenv/lib/python3.10/site-packages/asgiref/sync.py", line 534, in thread_handler
    raise exc_info[1]
  File "/home/mydjangoproject/myfiles/myvenv/lib/python3.10/site-packages/django/core/handlers/exception.py", line 42, in inner
    response = await get_response(request)
  File "/home/mydjangoproject/myfiles/myvenv/lib/python3.10/site-packages/django/core/handlers/base.py", line 253, in _get_response_async
    response = await wrapped_callback(
  File "/home/mydjangoproject/myfiles/myvenv/lib/python3.10/site-packages/asgiref/sync.py", line 479, in __call__
    ret: _R = await loop.run_in_executor(
  File "/usr/lib/python3.10/concurrent/futures/thread.py", line 58, in run
    result = self.fn(*self.args, **self.kwargs)
  File "/home/mydjangoproject/myfiles/myvenv/lib/python3.10/site-packages/asgiref/sync.py", line 538, in thread_handler
    return func(*args, **kwargs)
  File "/home/mydjangoproject/myfiles/myvenv/lib/python3.10/site-packages/django/contrib/admin/options.py", line 683, in wrapper
    return self.admin_site.admin_view(view)(*args, **kwargs)
  File "/home/mydjangoproject/myfiles/myvenv/lib/python3.10/site-packages/django/utils/decorators.py", line 133, in _wrapped_view
    response = view_func(request, *args, **kwargs)
  File "/home/mydjangoproject/myfiles/myvenv/lib/python3.10/site-packages/django/views/decorators/cache.py", line 62, in _wrapped_view_func
    response = view_func(request, *args, **kwargs)
  File "/home/mydjangoproject/myfiles/myvenv/lib/python3.10/site-packages/django/contrib/admin/sites.py", line 242, in inner
    return view(request, *args, **kwargs)
  File "/home/mydjangoproject/myfiles/myvenv/lib/python3.10/site-packages/django/utils/decorators.py", line 46, in _wrapper
    return bound_method(*args, **kwargs)
  File "/home/mydjangoproject/myfiles/myvenv/lib/python3.10/site-packages/django/utils/decorators.py", line 133, in _wrapped_view
    response = view_func(request, *args, **kwargs)
  File "/home/mydjangoproject/myfiles/myvenv/lib/python3.10/site-packages/django/contrib/admin/options.py", line 1926, in changelist_view
    cl = self.get_changelist_instance(request)
  File "/home/mydjangoproject/myfiles/myvenv/lib/python3.10/site-packages/django/contrib/admin/options.py", line 831, in get_changelist_instance
    return ChangeList(
  File "/home/mydjangoproject/myfiles/myvenv/lib/python3.10/site-packages/django/contrib/admin/views/main.py", line 123, in __init__
    self.get_results(request)
  File "/home/mydjangoproject/myfiles/myvenv/lib/python3.10/site-packages/django/contrib/admin/views/main.py", line 279, in get_results
    result_count = paginator.count
  File "/home/mydjangoproject/myfiles/myvenv/lib/python3.10/site-packages/django/utils/functional.py", line 49, in __get__
    res = instance.__dict__[self.name] = self.func(instance)
  File "/home/mydjangoproject/myfiles/myvenv/lib/python3.10/site-packages/django/core/paginator.py", line 96, in count
    return c()
  File "/home/mydjangoproject/myfiles/myvenv/lib/python3.10/site-packages/django/db/models/query.py", line 470, in count
    return self.query.get_count(using=self.db)
  File "/home/mydjangoproject/myfiles/myvenv/lib/python3.10/site-packages/django/db/models/sql/query.py", line 552, in get_count
    number = obj.get_aggregation(using, ["__count"])["__count"]
  File "/home/mydjangoproject/myfiles/myvenv/lib/python3.10/site-packages/django/db/models/sql/query.py", line 537, in get_aggregation
    result = compiler.execute_sql(SINGLE)
  File "/home/mydjangoproject/myfiles/myvenv/lib/python3.10/site-packages/django/db/models/sql/compiler.py", line 1361, in execute_sql
    cursor.execute(sql, params)
  File "/home/mydjangoproject/myfiles/myvenv/lib/python3.10/site-packages/django/db/backends/utils.py", line 103, in execute
    return super().execute(sql, params)
  File "/home/mydjangoproject/myfiles/myvenv/lib/python3.10/site-packages/django/db/backends/utils.py", line 67, in execute
    return self._execute_with_wrappers(
  File "/home/mydjangoproject/myfiles/myvenv/lib/python3.10/site-packages/django/db/backends/utils.py", line 80, in _execute_with_wrappers
    return executor(sql, params, many, context)
  File "/home/mydjangoproject/myfiles/myvenv/lib/python3.10/site-packages/django/db/backends/utils.py", line 84, in _execute
    with self.db.wrap_database_errors:
  File "/home/mydjangoproject/myfiles/myvenv/lib/python3.10/site-packages/django/db/utils.py", line 91, in __exit__
    raise dj_exc_value.with_traceback(traceback) from exc_value
  File "/home/mydjangoproject/myfiles/myvenv/lib/python3.10/site-packages/django/db/backends/utils.py", line 89, in _execute
    return self.cursor.execute(sql, params)
  File "/home/mydjangoproject/myfiles/myvenv/lib/python3.10/site-packages/django/db/backends/mysql/base.py", line 75, in execute
    return self.cursor.execute(query, args)
  File "/home/mydjangoproject/myfiles/myvenv/lib/python3.10/site-packages/MySQLdb/cursors.py", line 179, in execute
    res = self._query(mogrified_query)
  File "/home/mydjangoproject/myfiles/myvenv/lib/python3.10/site-packages/MySQLdb/cursors.py", line 330, in _query
    db.query(q)
  File "/home/mydjangoproject/myfiles/myvenv/lib/python3.10/site-packages/MySQLdb/connections.py", line 255, in query
    _mysql.connection.query(self, query)
django.db.utils.ProgrammingError: (1146, "Table 'Alertsystem.alertlog_roles' doesn't exist")
